Workbook

Sheet Лист1
A1: Артикул | B1: штрихкод | C1: Имя файла картинки для карточки | D1: Local_PDF_Path_Column_Name | E1: путь к печати | F1: Rotate | G1: Раскладка в ширину | H1: путь папки в облако | I1: место | J1: Предмет | K1: Бренд | L1: Цвет | M1: Пол | N1: Артикул продавца | O1: Артикул WB | P1: Наименование | Q1: Баркод товара | R1: Цена | S1: Состав | T1: Описание | U1: Высота упаковки | V1: Длина упаковки | W1: Ширина упаковки | X1: Вес товара с упаковкой (г) | Y1: Страна производства | Z1: Медиафайлы | AA1: OZON | AB1: НДС, %* | AC1: Включить продвижение | AD1: Ссылка на главное фото* | AE1: Ссылки на дополнительные фото | AF1: Название модели (для объединения в одну карточку)* | AG1: Цвет товара | AH1: Название цвета | AI1: Тип* | AJ1: Аннотация | AK1: Образец цвета | AL1: Ключевые слова | AM1: Вес в упаковке, г* | AN1: Ширина упаковки, мм* | AO1: Высота упаковки, мм* | AP1: Длина упаковки, мм* | AQ1: Тип упорядочить | AR1: SKU
A2: Термобирки Михаил | B2: OZN1295887283 | C2: Mihail | D2: =CONCATENATE("Documents\GitHub\Ozon_upload\barcode\бирки имена\мальчики\", A2, ".pdf") -> Documents\GitHub\Ozon_upload\barcode\бирки имена\мальчики\Термобирки Михаил.pdf | E2: =CONCATENATE("C:\Users\maxim\Documents\GitHub\Ozon_upload\DTF_images\names\мальчики\",,RIGHT(A2,LEN(A2)-FIND(" ",A2)),"_img.tif") -> C:\Users\maxim\Documents\GitHub\Ozon_upload\DTF_images\names\мальчики\Михаил_img.tif | F2: 1 | G2: 2 | I2: н1 | K2: Punky Monkey | N2: Documents\GitHub\Ozon_upload\barcode\бирки имена\мальчики\"; K2; ".pdf") | AB2: Не облагается | AM2: 16 | AN2: 180 | AO2: 1 | AP2: 250 | AQ2: 4_имена
A3: Термобирки Александр | B3: OZN1296040082 | C3: Alexandr | D3: =CONCATENATE("Documents\GitHub\Ozon_upload\barcode\бирки имена\мальчики\", A3, ".pdf") -> Documents\GitHub\Ozon_upload\barcode\бирки имена\мальчики\Термобирки Александр.pdf | E3: =CONCATENATE("C:\Users\maxim\Documents\GitHub\Ozon_upload\DTF_images\names\мальчики\",,RIGHT(A3,LEN(A3)-FIND(" ",A3)),"_img.tif") -> C:\Users\maxim\Documents\GitHub\Ozon_upload\DTF_images\names\мальчики\Александр_img.tif | F3: 1 | G3: 2 | I3: н2 | K3: Punky Monkey | AB3: Не облагается | AM3: 16 | AN3: 180 | AO3: 1 | AP3: 250 | AQ3: 4_имена
A4: Термобирки Максим | B4: OZN1296046505 | C4: Maxim | D4: =CONCATENATE("Documents\GitHub\Ozon_upload\barcode\бирки имена\мальчики\", A4, ".pdf") -> Documents\GitHub\Ozon_upload\barcode\бирки имена\мальчики\Термобирки Максим.pdf | E4: =CONCATENATE("C:\Users\maxim\Documents\GitHub\Ozon_upload\DTF_images\names\мальчики\",,RIGHT(A4,LEN(A4)-FIND(" ",A4)),"_img.tif") -> C:\Users\maxim\Documents\GitHub\Ozon_upload\DTF_images\names\мальчики\Максим_img.tif | F4: 1 | G4: 2 | I4: н3 | K4: Punky Monkey | AB4: Не облагается | AM4: 16 | AN4: 180 | AO4: 1 | AP4: 250 | AQ4: 4_имена
A5: Термобирки Артем | B5: OZN1296047725 | C5: Artem | D5: =CONCATENATE("Documents\GitHub\Ozon_upload\barcode\бирки имена\мальчики\", A5, ".pdf") -> Documents\GitHub\Ozon_upload\barcode\бирки имена\мальчики\Термобирки Артем.pdf | E5: =CONCATENATE("C:\Users\maxim\Documents\GitHub\Ozon_upload\DTF_images\names\мальчики\",,RIGHT(A5,LEN(A5)-FIND(" ",A5)),"_img.tif") -> C:\Users\maxim\Documents\GitHub\Ozon_upload\DTF_images\names\мальчики\Артем_img.tif | F5: 1 | G5: 2 | I5: н4 | K5: Punky Monkey | AB5: Не облагается | AM5: 16 | AN5: 180 | AO5: 1 | AP5: 250 | AQ5: 4_имена
A6: Термобирки Марк | B6: OZN1296049140 | C6: Mark | D6: =CONCATENATE("Documents\GitHub\Ozon_upload\barcode\бирки имена\мальчики\", A6, ".pdf") -> Documents\GitHub\Ozon_upload\barcode\бирки имена\мальчики\Термобирки Марк.pdf | E6: =CONCATENATE("C:\Users\maxim\Documents\GitHub\Ozon_upload\DTF_images\names\мальчики\",,RIGHT(A6,LEN(A6)-FIND(" ",A6)),"_img.tif") -> C:\Users\maxim\Documents\GitHub\Ozon_upload\DTF_images\names\мальчики\Марк_img.tif | F6: 1 | G6: 2 | I6: н5 | K6: Punky Monkey | AB6: Не облагается | AM6: 16 | AN6: 180 | AO6: 1 | AP6: 250 | AQ6: 4_имена
A7: Термобирки Лев | B7: OZN1296049859 | C7: Lev | D7: =CONCATENATE("Documents\GitHub\Ozon_upload\barcode\бирки имена\мальчики\", A7, ".pdf") -> Documents\GitHub\Ozon_upload\barcode\бирки имена\мальчики\Термобирки Лев.pdf | E7: =CONCATENATE("C:\Users\maxim\Documents\GitHub\Ozon_upload\DTF_images\names\мальчики\",,RIGHT(A7,LEN(A7)-FIND(" ",A7)),"_img.tif") -> C:\Users\maxim\Documents\GitHub\Ozon_upload\DTF_images\names\мальчики\Лев_img.tif | F7: 1 | G7: 2 | I7: н6 | K7: Punky Monkey | AB7: Не облагается | AM7: 16 | AN7: 180 | AO7: 1 | AP7: 250 | AQ7: 4_имена
A8: Термобирки Иван | B8: OZN1296050885 | C8: Ivan | D8: =CONCATENATE("Documents\GitHub\Ozon_upload\barcode\бирки имена\мальчики\", A8, ".pdf") -> Documents\GitHub\Ozon_upload\barcode\бирки имена\мальчики\Термобирки Иван.pdf | E8: =CONCATENATE("C:\Users\maxim\Documents\GitHub\Ozon_upload\DTF_images\names\мальчики\",,RIGHT(A8,LEN(A8)-FIND(" ",A8)),"_img.tif") -> C:\Users\maxim\Documents\GitHub\Ozon_upload\DTF_images\names\мальчики\Иван_img.tif | F8: 1 | G8: 2 | I8: н7 | K8: Punky Monkey | AB8: Не облагается | AM8: 16 | AN8: 180 | AO8: 1 | AP8: 250 | AQ8: 4_имена
A9: Термобирки Матвей | B9: OZN1296052287 | C9: Matvey | D9: =CONCATENATE("Documents\GitHub\Ozon_upload\barcode\бирки имена\мальчики\", A9, ".pdf") -> Documents\GitHub\Ozon_upload\barcode\бирки имена\мальчики\Термобирки Матвей.pdf | E9: =CONCATENATE("C:\Users\maxim\Documents\GitHub\Ozon_upload\DTF_images\names\мальчики\",,RIGHT(A9,LEN(A9)-FIND(" ",A9)),"_img.tif") -> C:\Users\maxim\Documents\GitHub\Ozon_upload\DTF_images\names\мальчики\Матвей_img.tif | F9: 1 | G9: 2 | I9: н8 | K9: Punky Monkey | AB9: Не облагается | AM9: 16 | AN9: 180 | AO9: 1 | AP9: 250 | AQ9: 4_имена
A10: Термобирки Даниил | B10: OZN1296053030 | C10: Daniil | D10: =CONCATENATE("Documents\GitHub\Ozon_upload\barcode\бирки имена\мальчики\", A10, ".pdf") -> Documents\GitHub\Ozon_upload\barcode\бирки имена\мальчики\Термобирки Даниил.pdf | E10: =CONCATENATE("C:\Users\maxim\Documents\GitHub\Ozon_upload\DTF_images\names\мальчики\",,RIGHT(A10,LEN(A10)-FIND(" ",A10)),"_img.tif") -> C:\Users\maxim\Documents\GitHub\Ozon_upload\DTF_images\names\мальчики\Даниил_img.tif | F10: 1 | G10: 2 | I10: н9 | K10: Punky Monkey | AB10: Не облагается | AM10: 16 | AN10: 180 | AO10: 1 | AP10: 250 | AQ10: 4_имена
A11: Термобирки Дмитрий | B11: OZN1296053164 | C11: Dmitriy | D11: =CONCATENATE("Documents\GitHub\Ozon_upload\barcode\бирки имена\мальчики\", A11, ".pdf") -> Documents\GitHub\Ozon_upload\barcode\бирки имена\мальчики\Термобирки Дмитрий.pdf | E11: =CONCATENATE("C:\Users\maxim\Documents\GitHub\Ozon_upload\DTF_images\names\мальчики\",,RIGHT(A11,LEN(A11)-FIND(" ",A11)),"_img.tif") -> C:\Users\maxim\Documents\GitHub\Ozon_upload\DTF_images\names\мальчики\Дмитрий_img.tif | F11: 1 | G11: 2 | I11: н10 | K11: Punky Monkey | AB11: Не облагается | AM11: 16 | AN11: 180 | AO11: 1 | AP11: 250 | AQ11: 4_имена
A12: Термобирки Тимофей | B12: OZN1296053524 | C12: Timofey | D12: =CONCATENATE("Documents\GitHub\Ozon_upload\barcode\бирки имена\мальчики\", A12, ".pdf") -> Documents\GitHub\Ozon_upload\barcode\бирки имена\мальчики\Термобирки Тимофей.pdf | E12: =CONCATENATE("C:\Users\maxim\Documents\GitHub\Ozon_upload\DTF_images\names\мальчики\",,RIGHT(A12,LEN(A12)-FIND(" ",A12)),"_img.tif") -> C:\Users\maxim\Documents\GitHub\Ozon_upload\DTF_images\names\мальчики\Тимофей_img.tif | F12: 1 | G12: 2 | I12: н11 | K12: Punky Monkey | AB12: Не облагается | AM12: 16 | AN12: 180 | AO12: 1 | AP12: 250 | AQ12: 4_имена
A13: Термобирки Роман | B13: OZN1296053904 | C13: Roman | D13: =CONCATENATE("Documents\GitHub\Ozon_upload\barcode\бирки имена\мальчики\", A13, ".pdf") -> Documents\GitHub\Ozon_upload\barcode\бирки имена\мальчики\Термобирки Роман.pdf | E13: =CONCATENATE("C:\Users\maxim\Documents\GitHub\Ozon_upload\DTF_images\names\мальчики\",,RIGHT(A13,LEN(A13)-FIND(" ",A13)),"_img.tif") -> C:\Users\maxim\Documents\GitHub\Ozon_upload\DTF_images\names\мальчики\Роман_img.tif | F13: 1 | G13: 2 | I13: н12 | K13: Punky Monkey | AB13: Не облагается | AM13: 16 | AN13: 180 | AO13: 1 | AP13: 250 | AQ13: 4_имена
A14: Термобирки Мирон | B14: OZN1296054484 | C14: Miron | D14: =CONCATENATE("Documents\GitHub\Ozon_upload\barcode\бирки имена\мальчики\", A14, ".pdf") -> Documents\GitHub\Ozon_upload\barcode\бирки имена\мальчики\Термобирки Мирон.pdf | E14: =CONCATENATE("C:\Users\maxim\Documents\GitHub\Ozon_upload\DTF_images\names\мальчики\",,RIGHT(A14,LEN(A14)-FIND(" ",A14)),"_img.tif") -> C:\Users\maxim\Documents\GitHub\Ozon_upload\DTF_images\names\мальчики\Мирон_img.tif | F14: 1 | G14: 2 | I14: н13 | K14: Punky Monkey | AB14: Не облагается | AM14: 16 | AN14: 180 | AO14: 1 | AP14: 250 | AQ14: 4_имена
... A41: Термобирки Мирослав | B41: OZN1296069108 | C41: Miroslav | D41: =CONCATENATE("Documents\GitHub\Ozon_upload\barcode\бирки имена\мальчики\", A41, ".pdf") -> Documents\GitHub\Ozon_upload\barcode\бирки имена\мальчики\Термобирки Мирослав.pdf | E41: =CONCATENATE("C:\Users\maxim\Documents\GitHub\Ozon_upload\DTF_images\names\мальчики\",,RIGHT(A41,LEN(A41)-FIND(" ",A41)),"_img.tif") -> C:\Users\maxim\Documents\GitHub\Ozon_upload\DTF_images\names\мальчики\Мирослав_img.tif | F41: 1 | G41: 2 | I41: н40 | K41: Punky Monkey | AB41: Не облагается | AM41: 16 | AN41: 180 | AO41: 1 | AP41: 250 | AQ41: 4_имена
A42: Термобирки София | B42: OZN1302305863 | C42: Sofia | D42: =CONCATENATE("Documents\GitHub\Ozon_upload\barcode\бирки имена\девочки\", A42, ".pdf") -> Documents\GitHub\Ozon_upload\barcode\бирки имена\девочки\Термобирки София.pdf | E42: =CONCATENATE("C:\Users\maxim\Documents\GitHub\Ozon_upload\DTF_images\names\девочки\",,RIGHT(A42,LEN(A42)-FIND(" ",A42)),"_img.tif") -> C:\Users\maxim\Documents\GitHub\Ozon_upload\DTF_images\names\девочки\София_img.tif | F42: 1 | G42: 2 | I42: н41 | K42: Punky Monkey | AB42: Не облагается | AM42: 16 | AN42: 180 | AO42: 1 | AP42: 250 | AQ42: 4_имена
A43: Термобирки Анна | B43: OZN1302411737 | C43: Анна | D43: =CONCATENATE("Documents\GitHub\Ozon_upload\barcode\бирки имена\девочки\", A43, ".pdf") -> Documents\GitHub\Ozon_upload\barcode\бирки имена\девочки\Термобирки Анна.pdf | E43: =CONCATENATE("C:\Users\maxim\Documents\GitHub\Ozon_upload\DTF_images\names\девочки\",,RIGHT(A43,LEN(A43)-FIND(" ",A43)),"_img.tif") -> C:\Users\maxim\Documents\GitHub\Ozon_upload\DTF_images\names\девочки\Анна_img.tif | F43: 1 | G43: 2 | I43: н42 | K43: Punky Monkey | AB43: Не облагается | AM43: 16 | AN43: 180 | AO43: 1 | AP43: 250 | AQ43: 4_имена
A44: Термобирки Мария | B44: OZN1302410399 | C44: Maria | D44: =CONCATENATE("Documents\GitHub\Ozon_upload\barcode\бирки имена\девочки\", A44, ".pdf") -> Documents\GitHub\Ozon_upload\barcode\бирки имена\девочки\Термобирки Мария.pdf | E44: =CONCATENATE("C:\Users\maxim\Documents\GitHub\Ozon_upload\DTF_images\names\девочки\",,RIGHT(A44,LEN(A44)-FIND(" ",A44)),"_img.tif") -> C:\Users\maxim\Documents\GitHub\Ozon_upload\DTF_images\names\девочки\Мария_img.tif | F44: 1 | G44: 2 | I44: н43 | K44: Punky Monkey | AB44: Не облагается | AM44: 16 | AN44: 180 | AO44: 1 | AP44: 250 | AQ44: 4_имена
A45: Термобирки Ева | B45: OZN1302409528 | C45: Eva | D45: =CONCATENATE("Documents\GitHub\Ozon_upload\barcode\бирки имена\девочки\", A45, ".pdf") -> Documents\GitHub\Ozon_upload\barcode\бирки имена\девочки\Термобирки Ева.pdf | E45: =CONCATENATE("C:\Users\maxim\Documents\GitHub\Ozon_upload\DTF_images\names\девочки\",,RIGHT(A45,LEN(A45)-FIND(" ",A45)),"_img.tif") -> C:\Users\maxim\Documents\GitHub\Ozon_upload\DTF_images\names\девочки\Ева_img.tif | F45: 1 | G45: 2 | I45: н44 | K45: Punky Monkey | AB45: Не облагается | AM45: 16 | AN45: 180 | AO45: 1 | AP45: 250 | AQ45: 4_имена
A46: Термобирки Алиса | B46: OZN1302409496 | C46: Alisa | D46: =CONCATENATE("Documents\GitHub\Ozon_upload\barcode\бирки имена\девочки\", A46, ".pdf") -> Documents\GitHub\Ozon_upload\barcode\бирки имена\девочки\Термобирки Алиса.pdf | E46: =CONCATENATE("C:\Users\maxim\Documents\GitHub\Ozon_upload\DTF_images\names\девочки\",,RIGHT(A46,LEN(A46)-FIND(" ",A46)),"_img.tif") -> C:\Users\maxim\Documents\GitHub\Ozon_upload\DTF_images\names\девочки\Алиса_img.tif | F46: 1 | G46: 2 | I46: н45 | K46: Punky Monkey | AB46: Не облагается | AM46: 16 | AN46: 180 | AO46: 1 | AP46: 250 | AQ46: 4_имена
A47: Термобирки Есения | B47: OZN1302409123 | C47: Eseniya | D47: =CONCATENATE("Documents\GitHub\Ozon_upload\barcode\бирки имена\девочки\", A47, ".pdf") -> Documents\GitHub\Ozon_upload\barcode\бирки имена\девочки\Термобирки Есения.pdf | E47: =CONCATENATE("C:\Users\maxim\Documents\GitHub\Ozon_upload\DTF_images\names\девочки\",,RIGHT(A47,LEN(A47)-FIND(" ",A47)),"_img.tif") -> C:\Users\maxim\Documents\GitHub\Ozon_upload\DTF_images\names\девочки\Есения_img.tif | F47: 1 | G47: 2 | I47: н46 | K47: Punky Monkey | AB47: Не облагается | AM47: 16 | AN47: 180 | AO47: 1 | AP47: 250 | AQ47: 4_имена
A48: Термобирки Екатерина | B48: OZN1302407604 | C48: Ekaterina | D48: =CONCATENATE("Documents\GitHub\Ozon_upload\barcode\бирки имена\девочки\", A48, ".pdf") -> Documents\GitHub\Ozon_upload\barcode\бирки имена\девочки\Термобирки Екатерина.pdf | E48: =CONCATENATE("C:\Users\maxim\Documents\GitHub\Ozon_upload\DTF_images\names\девочки\",,RIGHT(A48,LEN(A48)-FIND(" ",A48)),"_img.tif") -> C:\Users\maxim\Documents\GitHub\Ozon_upload\DTF_images\names\девочки\Екатерина_img.tif | F48: 1 | G48: 2 | I48: н47 | K48: Punky Monkey | AB48: Не облагается | AM48: 16 | AN48: 180 | AO48: 1 | AP48: 250 | AQ48: 4_имена
A49: Термобирки Светлана | B49: OZN1302408948 | C49: Svetlana | D49: =CONCATENATE("Documents\GitHub\Ozon_upload\barcode\бирки имена\девочки\", A49, ".pdf") -> Documents\GitHub\Ozon_upload\barcode\бирки имена\девочки\Термобирки Светлана.pdf | E49: =CONCATENATE("C:\Users\maxim\Documents\GitHub\Ozon_upload\DTF_images\names\девочки\",,RIGHT(A49,LEN(A49)-FIND(" ",A49)),"_img.tif") -> C:\Users\maxim\Documents\GitHub\Ozon_upload\DTF_images\names\девочки\Светлана_img.tif | F49: 1 | G49: 2 | I49: н48 | K49: Punky Monkey | AB49: Не облагается | AM49: 16 | AN49: 180 | AO49: 1 | AP49: 250 | AQ49: 4_имена
A50: Термобирки Полина | B50: OZN1302409185 | C50: Polina | D50: =CONCATENATE("Documents\GitHub\Ozon_upload\barcode\бирки имена\девочки\", A50, ".pdf") -> Documents\GitHub\Ozon_upload\barcode\бирки имена\девочки\Термобирки Полина.pdf | E50: =CONCATENATE("C:\Users\maxim\Documents\GitHub\Ozon_upload\DTF_images\names\девочки\",,RIGHT(A50,LEN(A50)-FIND(" ",A50)),"_img.tif") -> C:\Users\maxim\Documents\GitHub\Ozon_upload\DTF_images\names\девочки\Полина_img.tif | F50: 1 | G50: 2 | I50: н49 | K50: Punky Monkey | AB50: Не облагается | AM50: 16 | AN50: 180 | AO50: 1 | AP50: 250 | AQ50: 4_имена
A51: Термобирки Оливия | B51: OZN1302409422 | C51: Olivia | D51: =CONCATENATE("Documents\GitHub\Ozon_upload\barcode\бирки имена\девочки\", A51, ".pdf") -> Documents\GitHub\Ozon_upload\barcode\бирки имена\девочки\Термобирки Оливия.pdf | E51: =CONCATENATE("C:\Users\maxim\Documents\GitHub\Ozon_upload\DTF_images\names\девочки\",,RIGHT(A51,LEN(A51)-FIND(" ",A51)),"_img.tif") -> C:\Users\maxim\Documents\GitHub\Ozon_upload\DTF_images\names\девочки\Оливия_img.tif | F51: 1 | G51: 2 | I51: н50 | K51: Punky Monkey | AB51: Не облагается | AM51: 16 | AN51: 180 | AO51: 1 | AP51: 250 | AQ51: 4_имена
A52: Термобирки Агата | B52: OZN1302409156 | C52: Agata | D52: =CONCATENATE("Documents\GitHub\Ozon_upload\barcode\бирки имена\девочки\", A52, ".pdf") -> Documents\GitHub\Ozon_upload\barcode\бирки имена\девочки\Термобирки Агата.pdf | E52: =CONCATENATE("C:\Users\maxim\Documents\GitHub\Ozon_upload\DTF_images\names\девочки\",,RIGHT(A52,LEN(A52)-FIND(" ",A52)),"_img.tif") -> C:\Users\maxim\Documents\GitHub\Ozon_upload\DTF_images\names\девочки\Агата_img.tif | F52: 1 | G52: 2 | I52: н51 | K52: Punky Monkey | AB52: Не облагается | AM52: 16 | AN52: 180 | AO52: 1 | AP52: 250 | AQ52: 4_имена
A53: Термобирки Милана | B53: OZN1302408933 | C53: Milana | D53: =CONCATENATE("Documents\GitHub\Ozon_upload\barcode\бирки имена\девочки\", A53, ".pdf") -> Documents\GitHub\Ozon_upload\barcode\бирки имена\девочки\Термобирки Милана.pdf | E53: =CONCATENATE("C:\Users\maxim\Documents\GitHub\Ozon_upload\DTF_images\names\девочки\",,RIGHT(A53,LEN(A53)-FIND(" ",A53)),"_img.tif") -> C:\Users\maxim\Documents\GitHub\Ozon_upload\DTF_images\names\девочки\Милана_img.tif | F53: 1 | G53: 2 | I53: н52 | K53: Punky Monkey | AB53: Не облагается | AM53: 16 | AN53: 180 | AO53: 1 | AP53: 250 | AQ53: 4_имена
... A81: Термобирки Аделина | B81: OZN1302409334 | C81: Adelina | D81: =CONCATENATE("Documents\GitHub\Ozon_upload\barcode\бирки имена\девочки\", A81, ".pdf") -> Documents\GitHub\Ozon_upload\barcode\бирки имена\девочки\Термобирки Аделина.pdf | E81: =CONCATENATE("C:\Users\maxim\Documents\GitHub\Ozon_upload\DTF_images\names\девочки\",,RIGHT(A81,LEN(A81)-FIND(" ",A81)),"_img.tif") -> C:\Users\maxim\Documents\GitHub\Ozon_upload\DTF_images\names\девочки\Аделина_img.tif | F81: 1 | G81: 2 | I81: н80 | K81: Punky Monkey | AB81: Не облагается | AM81: 16 | AN81: 180 | AO81: 1 | AP81: 250 | AQ81: 4_имена
A82: Термобирки Владимир | B82: OZN1325160332 | C82: Vladimir | D82: =CONCATENATE("Documents\GitHub\Ozon_upload\barcode\бирки имена\мальчики\", A82, ".pdf") -> Documents\GitHub\Ozon_upload\barcode\бирки имена\мальчики\Термобирки Владимир.pdf | E82: =CONCATENATE("C:\Users\maxim\Documents\GitHub\Ozon_upload\DTF_images\names\мальчики\",,RIGHT(A82,LEN(A82)-FIND(" ",A82)),"_img.tif") -> C:\Users\maxim\Documents\GitHub\Ozon_upload\DTF_images\names\мальчики\Владимир_img.tif | F82: 1 | G82: 2 | I82: н81 | K82: Punky Monkey | AB82: Не облагается | AM82: 16 | AN82: 180 | AO82: 1 | AP82: 250 | AQ82: 4_имена
A83: Термобирки Ярослав | B83: OZN1325161455 | C83: Yaroslav | D83: =CONCATENATE("Documents\GitHub\Ozon_upload\barcode\бирки имена\мальчики\", A83, ".pdf") -> Documents\GitHub\Ozon_upload\barcode\бирки имена\мальчики\Термобирки Ярослав.pdf | E83: =CONCATENATE("C:\Users\maxim\Documents\GitHub\Ozon_upload\DTF_images\names\мальчики\",,RIGHT(A83,LEN(A83)-FIND(" ",A83)),"_img.tif") -> C:\Users\maxim\Documents\GitHub\Ozon_upload\DTF_images\names\мальчики\Ярослав_img.tif | F83: 1 | G83: 2 | I83: н82 | K83: Punky Monkey | AB83: Не облагается | AM83: 16 | AN83: 180 | AO83: 1 | AP83: 250 | AQ83: 4_имена
A84: Термобирки Семён | B84: OZN1325162457 | C84: Semen | D84: =CONCATENATE("Documents\GitHub\Ozon_upload\barcode\бирки имена\мальчики\", A84, ".pdf") -> Documents\GitHub\Ozon_upload\barcode\бирки имена\мальчики\Термобирки Семён.pdf | E84: =CONCATENATE("C:\Users\maxim\Documents\GitHub\Ozon_upload\DTF_images\names\мальчики\",,RIGHT(A84,LEN(A84)-FIND(" ",A84)),"_img.tif") -> C:\Users\maxim\Documents\GitHub\Ozon_upload\DTF_images\names\мальчики\Семён_img.tif | F84: 1 | G84: 2 | I84: н83 | K84: Punky Monkey | AB84: Не облагается | AM84: 16 | AN84: 180 | AO84: 1 | AP84: 250 | AQ84: 4_имена
A85: Термобирки Сергей | B85: OZN1325163089 | C85: Sergey | D85: =CONCATENATE("Documents\GitHub\Ozon_upload\barcode\бирки имена\мальчики\", A85, ".pdf") -> Documents\GitHub\Ozon_upload\barcode\бирки имена\мальчики\Термобирки Сергей.pdf | E85: =CONCATENATE("C:\Users\maxim\Documents\GitHub\Ozon_upload\DTF_images\names\мальчики\",,RIGHT(A85,LEN(A85)-FIND(" ",A85)),"_img.tif") -> C:\Users\maxim\Documents\GitHub\Ozon_upload\DTF_images\names\мальчики\Сергей_img.tif | F85: 1 | G85: 2 | I85: н84 | K85: Punky Monkey | AB85: Не облагается | AM85: 16 | AN85: 180 | AO85: 1 | AP85: 250 | AQ85: 4_имена
A86: Термобирки Степан | B86: OZN1325163507 | C86: Stepan | D86: =CONCATENATE("Documents\GitHub\Ozon_upload\barcode\бирки имена\мальчики\", A86, ".pdf") -> Documents\GitHub\Ozon_upload\barcode\бирки имена\мальчики\Термобирки Степан.pdf | E86: =CONCATENATE("C:\Users\maxim\Documents\GitHub\Ozon_upload\DTF_images\names\мальчики\",,RIGHT(A86,LEN(A86)-FIND(" ",A86)),"_img.tif") -> C:\Users\maxim\Documents\GitHub\Ozon_upload\DTF_images\names\мальчики\Степан_img.tif | F86: 1 | G86: 2 | I86: н85 | K86: Punky Monkey | AB86: Не облагается | AM86: 16 | AN86: 180 | AO86: 1 | AP86: 250 | AQ86: 4_имена
A87: Термобирки Данил | B87: OZN1325164077 | C87: Danil | D87: =CONCATENATE("Documents\GitHub\Ozon_upload\barcode\бирки имена\мальчики\", A87, ".pdf") -> Documents\GitHub\Ozon_upload\barcode\бирки имена\мальчики\Термобирки Данил.pdf | E87: =CONCATENATE("C:\Users\maxim\Documents\GitHub\Ozon_upload\DTF_images\names\мальчики\",,RIGHT(A87,LEN(A87)-FIND(" ",A87)),"_img.tif") -> C:\Users\maxim\Documents\GitHub\Ozon_upload\DTF_images\names\мальчики\Данил_img.tif | F87: 1 | G87: 2 | I87: н86 | K87: Punky Monkey | AB87: Не облагается | AM87: 16 | AN87: 180 | AO87: 1 | AP87: 250 | AQ87: 4_имена
A88: Термобирки Аглая | B88: OZN2366379897 | C88: Aglaya | D88: =CONCATENATE("Documents\GitHub\Ozon_upload\barcode\бирки имена\new\", A88, ".pdf") -> Documents\GitHub\Ozon_upload\barcode\бирки имена\new\Термобирки Аглая.pdf | E88: =CONCATENATE("C:\Users\maxim\Documents\GitHub\Ozon_upload\DTF_images\names\девочки\",,RIGHT(A88,LEN(A88)-FIND(" ",A88)),"_img.tif") -> C:\Users\maxim\Documents\GitHub\Ozon_upload\DTF_images\names\девочки\Аглая_img.tif | F88: 1 | G88: 2 | I88: н87 | K88: Punky Monkey | AB88: Не облагается | AM88: 16 | AN88: 180 | AO88: 1 | AP88: 250 | AQ88: 4_имена
A89: Термобирки Виолетта | B89: OZN2366379413 | C89: Violetta | D89: =CONCATENATE("Documents\GitHub\Ozon_upload\barcode\бирки имена\new\", A89, ".pdf") -> Documents\GitHub\Ozon_upload\barcode\бирки имена\new\Термобирки Виолетта.pdf | E89: =CONCATENATE("C:\Users\maxim\Documents\GitHub\Ozon_upload\DTF_images\names\девочки\",,RIGHT(A89,LEN(A89)-FIND(" ",A89)),"_img.tif") -> C:\Users\maxim\Documents\GitHub\Ozon_upload\DTF_images\names\девочки\Виолетта_img.tif | F89: 1 | G89: 2 | I89: н88 | K89: Punky Monkey | AB89: Не облагается | AM89: 16 | AN89: 180 | AO89: 1 | AP89: 250 | AQ89: 4_имена
A90: Термобирки Кристина | B90: OZN2366379589 | C90: Kristina | D90: =CONCATENATE("Documents\GitHub\Ozon_upload\barcode\бирки имена\new\", A90, ".pdf") -> Documents\GitHub\Ozon_upload\barcode\бирки имена\new\Термобирки Кристина.pdf | E90: =CONCATENATE("C:\Users\maxim\Documents\GitHub\Ozon_upload\DTF_images\names\девочки\",,RIGHT(A90,LEN(A90)-FIND(" ",A90)),"_img.tif") -> C:\Users\maxim\Documents\GitHub\Ozon_upload\DTF_images\names\девочки\Кристина_img.tif | F90: 1 | G90: 2 | I90: н89 | K90: Punky Monkey | AB90: Не облагается | AM90: 16 | AN90: 180 | AO90: 1 | AP90: 250 | AQ90: 4_имена
A91: Термобирки Марьяна | B91: OZN2366379582 | C91: Maryana | D91: =CONCATENATE("Documents\GitHub\Ozon_upload\barcode\бирки имена\new\", A91, ".pdf") -> Documents\GitHub\Ozon_upload\barcode\бирки имена\new\Термобирки Марьяна.pdf | E91: =CONCATENATE("C:\Users\maxim\Documents\GitHub\Ozon_upload\DTF_images\names\девочки\",,RIGHT(A91,LEN(A91)-FIND(" ",A91)),"_img.tif") -> C:\Users\maxim\Documents\GitHub\Ozon_upload\DTF_images\names\девочки\Марьяна_img.tif | F91: 1 | G91: 2 | I91: н90 | K91: Punky Monkey | AB91: Не облагается | AM91: 16 | AN91: 180 | AO91: 1 | AP91: 250 | AQ91: 4_имена
A92: Термобирки Маргарита | B92: OZN2366390031 | C92: Margarita | D92: =CONCATENATE("Documents\GitHub\Ozon_upload\barcode\бирки имена\new\", A92, ".pdf") -> Documents\GitHub\Ozon_upload\barcode\бирки имена\new\Термобирки Маргарита.pdf | E92: =CONCATENATE("C:\Users\maxim\Documents\GitHub\Ozon_upload\DTF_images\names\девочки\",,RIGHT(A92,LEN(A92)-FIND(" ",A92)),"_img.tif") -> C:\Users\maxim\Documents\GitHub\Ozon_upload\DTF_images\names\девочки\Маргарита_img.tif | F92: 1 | G92: 2 | I92: н91 | K92: Punky Monkey | AB92: Не облагается | AM92: 16 | AN92: 180 | AO92: 1 | AP92: 250 | AQ92: 4_имена
A93: Термобирки Ульяна | B93: OZN2366379751 | C93: Ulyana | D93: =CONCATENATE("Documents\GitHub\Ozon_upload\barcode\бирки имена\new\", A93, ".pdf") -> Documents\GitHub\Ozon_upload\barcode\бирки имена\new\Термобирки Ульяна.pdf | E93: =CONCATENATE("C:\Users\maxim\Documents\GitHub\Ozon_upload\DTF_images\names\девочки\",,RIGHT(A93,LEN(A93)-FIND(" ",A93)),"_img.tif") -> C:\Users\maxim\Documents\GitHub\Ozon_upload\DTF_images\names\девочки\Ульяна_img.tif | F93: 1 | G93: 2 | I93: н92 | K93: Punky Monkey | AB93: Не облагается | AM93: 16 | AN93: 180 | AO93: 1 | AP93: 250 | AQ93: 4_имена
...

Sheet номер
A1: 1
A2: =A1+1 -> 2
A3: =A2+1 -> 3
A4: =A3+1 -> 4
A5: =A4+1 -> 5
A6: =A5+1 -> 6
A7: =A6+1 -> 7
A8: =A7+1 -> 8
A9: =A8+1 -> 9
A10: =A9+1 -> 10
A11: =A10+1 -> 11
A12: =A11+1 -> 12
A13: =A12+1 -> 13
... A654: =A653+1 -> 654

Sheet Sheet2
A2: Термонаклейка Девушка волосы облако Тест
A3: Термобирки Михаил | B3: имена
A4: Термобирки Александр | B4: имена
A5: Термобирки Максим | B5: имена
A6: Термобирки Артем | B6: имена
A7: Термобирки Марк | B7: имена
A8: Термобирки Лев | B8: имена
A9: Термобирки Иван | B9: имена
A10: Термобирки Матвей | B10: имена
A11: Термобирки Даниил | B11: имена
A12: Термобирки Дмитрий | B12: имена
A13: Термобирки Тимофей | B13: имена
A14: Термобирки Роман | B14: имена
... A241: Термонаклейка Единорог корона и надпись внизу | B241: а5

Sheet username
A1: maxim
A2: maxim
A3: maxim
A4: maxim
A5: maxim
A6: maxim
A7: maxim
A8: maxim
A9: maxim
A10: maxim
A11: maxim
A12: maxim
... A1592: maxim

Sheet username2
A1: maxim | B1: maxim
A2: maxim | B2: maxim
A3: maxim | B3: maxim
A4: maxim | B4: maxim
A5: maxim | B5: maxim
A6: maxim | B6: maxim
A7: maxim | B7: maxim
A8: maxim | B8: maxim
A9: maxim | B9: maxim
A10: maxim | B10: maxim
A11: maxim | B11: maxim
A12: maxim | B12: maxim
... A629: maxim | B629: maxim
